Workbook
Name ВременнаяШкала_Order_Date: #N/A
Name Срез_Customer_Name: #N/A
Name Срез_Product_Category: #N/A
Name Срез_Product_Sub_Category: #N/A

Sheet Orders
A1: Row ID | B1: Order Priority | C1: Discount | D1: Unit Price | E1: Shipping Cost | F1: Customer ID | G1: Customer Name | H1: Ship Mode | I1: Customer Segment | J1: Product Category | K1: Product Sub-Category | L1: Product Container | M1: Product Name | N1: Product Base Margin | O1: Country | P1: Region | Q1: State or Province | R1: City | S1: Postal Code | T1: Order Date | U1: Ship Date | V1: Profit | W1: Quantity ordered new | X1: Sales | Y1: Order ID
A2: 20847 | B2: High | C2: 0.01 | D2: 2.84 | E2: 0.93 | F2: 3 | G2: Bonnie Potter | H2: Express Air | I2: Corporate | J2: Office Supplies | K2: Pens & Art Supplies | L2: Wrap Bag | M2: SANFORD Liquid Accent™ Tank-Style Highlighters | N2: 0.54 | O2: United States | P2: West | Q2: Washington | R2: Anacortes | S2: 98221 | T2: 42011 | U2: 42012 | V2: 4.56 | W2: 4 | X2: 13.01 | Y2: 88522
A3: 20228 | B3: Not Specified | C3: 0.02 | D3: 500.98 | E3: 26 | F3: 5 | G3: Ronnie Proctor | H3: Delivery Truck | I3: Home Office | J3: Furniture | K3: Chairs & Chairmats | L3: Jumbo Drum | M3: Global Troy™ Executive Leather Low-Back Tilter | N3: 0.6 | O3: United States | P3: West | Q3: California | R3: San Gabriel | S3: 91776 | T3: 42168 | U3: 42170 | V3: 4390.3665 | W3: 12 | X3: 6362.85 | Y3: 90193
A4: 21776 | B4: Critical | C4: 0.06 | D4: 9.48 | E4: 7.29 | F4: 11 | G4: Marcus Dunlap | H4: Regular Air | I4: Home Office | J4: Furniture | K4: Office Furnishings | L4: Small Pack | M4: DAX Two-Tone Rosewood/Black Document Frame, Desktop, 5 x 7 | N4: 0.45 | O4: United States | P4: East | Q4: New Jersey | R4: Roselle | S4: 7203 | T4: 42050 | U4: 42052 | V4: -53.8096 | W4: 22 | X4: 211.15 | Y4: 90192
A5: 24844 | B5: Medium | C5: 0.09 | D5: 78.69 | E5: 19.99 | F5: 14 | G5: Gwendolyn F Tyson | H5: Regular Air | I5: Small Business | J5: Furniture | K5: Office Furnishings | L5: Small Box | M5: Howard Miller 12-3/4 Diameter Accuwave DS ™ Wall Clock | N5: 0.43 | O5: United States | P5: Central | Q5: Minnesota | R5: Prior Lake | S5: 55372 | T5: 42136 | U5: 42138 | V5: 803.4705 | W5: 16 | X5: 1164.45 | Y5: 86838
A6: 24846 | B6: Medium | C6: 0.08 | D6: 3.28 | E6: 2.31 | F6: 14 | G6: Gwendolyn F Tyson | H6: Regular Air | I6: Small Business | J6: Office Supplies | K6: Pens & Art Supplies | L6: Wrap Bag | M6: Newell 321 | N6: 0.56 | O6: United States | P6: Central | Q6: Minnesota | R6: Prior Lake | S6: 55372 | T6: 42136 | U6: 42137 | V6: -24.03 | W6: 7 | X6: 22.23 | Y6: 86838
A7: 24847 | B7: Medium | C7: 0.05 | D7: 3.28 | E7: 4.2 | F7: 14 | G7: Gwendolyn F Tyson | H7: Regular Air | I7: Small Business | J7: Office Supplies | K7: Pens & Art Supplies | L7: Wrap Bag | M7: Newell 351 | N7: 0.56 | O7: United States | P7: Central | Q7: Minnesota | R7: Prior Lake | S7: 55372 | T7: 42136 | U7: 42137 | V7: -37.03 | W7: 4 | X7: 13.99 | Y7: 86838
A8: 24848 | B8: Medium | C8: 0.05 | D8: 3.58 | E8: 1.63 | F8: 14 | G8: Gwendolyn F Tyson | H8: Regular Air | I8: Small Business | J8: Office Supplies | K8: Rubber Bands | L8: Wrap Bag | M8: OIC Colored Binder Clips, Assorted Sizes | N8: 0.36 | O8: United States | P8: Central | Q8: Minnesota | R8: Prior Lake | S8: 55372 | T8: 42136 | U8: 42137 | V8: -0.71 | W8: 4 | X8: 14.26 | Y8: 86838
A9: 18181 | B9: Critical | C9: 0 | D9: 4.42 | E9: 4.99 | F9: 15 | G9: Timothy Reese | H9: Regular Air | I9: Small Business | J9: Office Supplies | K9: Envelopes | L9: Small Box | M9: Grip Seal Envelopes | N9: 0.38 | O9: United States | P9: East | Q9: New York | R9: Smithtown | S9: 11787 | T9: 42102 | U9: 42103 | V9: -59.82 | W9: 7 | X9: 33.47 | Y9: 86837
A10: 20925 | B10: Medium | C10: 0.01 | D10: 35.94 | E10: 6.66 | F10: 15 | G10: Timothy Reese | H10: Regular Air | I10: Small Business | J10: Office Supplies | K10: Envelopes | L10: Small Box | M10: Tyvek ® Top-Opening Peel & Seel ® Envelopes, Gray | N10: 0.4 | O10: United States | P10: East | Q10: New York | R10: Smithtown | S10: 11787 | T10: 42152 | U10: 42152 | V10: 261.8757 | W10: 10 | X10: 379.53 | Y10: 86839
A11: 26267 | B11: High | C11: 0.04 | D11: 2.98 | E11: 1.58 | F11: 16 | G11: Sarah Ramsey | H11: Regular Air | I11: Small Business | J11: Office Supplies | K11: Rubber Bands | L11: Wrap Bag | M11: Staples Gold Paper Clips | N11: 0.39 | O11: United States | P11: East | Q11: New York | R11: Syracuse | S11: 13210 | T11: 42047 | U11: 42050 | V11: 2.63 | W11: 6 | X11: 18.8 | Y11: 86836
A12: 26268 | B12: High | C12: 0.05 | D12: 115.99 | E12: 2.5 | F12: 16 | G12: Sarah Ramsey | H12: Regular Air | I12: Small Business | J12: Technology | K12: Telephones and Communication | L12: Small Box | M12: StarTAC 7797 | N12: 0.55 | O12: United States | P12: East | Q12: New York | R12: Syracuse | S12: 13210 | T12: 42047 | U12: 42049 | V12: 652.7331 | W12: 10 | X12: 945.99 | Y12: 86836
A13: 23890 | B13: High | C13: 0.05 | D13: 26.48 | E13: 6.93 | F13: 18 | G13: Laurie Hanna | H13: Regular Air | I13: Small Business | J13: Furniture | K13: Office Furnishings | L13: Small Box | M13: DAX Natural Wood-Tone Poster Frame | N13: 0.49 | O13: United States | P13: West | Q13: Montana | R13: Helena | S13: 59601 | T13: 42139 | U13: 42140 | V13: 314.4813 | W13: 17 | X13: 455.77 | Y13: 90031
... A182: 19158 | B182: Medium | C182: 0.01 | D182: 29.1 | E182: 4 | F182: 331 | G182: Bradley Pollock | H182: Express Air | I182: Home Office | J182: Technology | K182: Computer Peripherals | L182: Small Box | M182: Acco Keyboard-In-A-Box® | N182: 0.78 | O182: United States | P182: East | Q182: New Hampshire | R182: Goffstown | S182: 3045 | T182: 42108 | U182: 42110 | V182: -22.82 | W182: 8 | X182: 243.32 | Y182: 89726
A183: 18261 | B183: Critical | C183: 0.06 | D183: 276.2 | E183: 24.49 | F183: 335 | G183: Curtis O'Connell | H183: Regular Air | I183: Corporate | J183: Furniture | K183: Chairs & Chairmats | L183: Large Box | M183: SAFCO Arco Folding Chair | O183: United States | P183: West | Q183: Oregon | R183: Medford | S183: 97504 | T183: 42128 | U183: 42129 | V183: 2639.4708 | W183: 14 | X183: 3825.32 | Y183: 87277
A184: 18262 | B184: Critical | C184: 0.09 | D184: 6.28 | E184: 5.29 | F184: 335 | G184: Curtis O'Connell | H184: Regular Air | I184: Corporate | J184: Furniture | K184: Office Furnishings | L184: Small Box | M184: Eldon® 200 Class™ Desk Accessories, Burgundy | N184: 0.43 | O184: United States | P184: West | Q184: Oregon | R184: Medford | S184: 97504 | T184: 42128 | U184: 42128 | V184: -5.2 | W184: 1 | X184: 8.53 | Y184: 87277
A185: 23481 | B185: Medium | C185: 0.08 | D185: 7.77 | E185: 9.23 | F185: 339 | G185: Bobby Clements | H185: Regular Air | I185: Corporate | J185: Office Supplies | K185: Appliances | L185: Small Box | M185: Hoover Commercial Soft Guard Upright Vacuum And Disposable Filtration Bags | N185: 0.58 | O185: United States | P185: East | Q185: Ohio | R185: Columbus | S185: 43229 | T185: 42080 | U185: 42081 | V185: -83.65 | W185: 5 | X185: 40.3 | Y185: 90583
A186: 23482 | B186: Medium | C186: 0.07 | D186: 7.59 | E186: 4 | F186: 339 | G186: Bobby Clements | H186: Regular Air | I186: Corporate | J186: Furniture | K186: Office Furnishings | L186: Wrap Bag | M186: Master Giant Foot® Doorstop, Safety Yellow | N186: 0.42 | O186: United States | P186: East | Q186: Ohio | R186: Columbus | S186: 43229 | T186: 42080 | U186: 42082 | V186: 24.39 | W186: 15 | X186: 111.88 | Y186: 90583
A187: 480 | B187: Critical | C187: 0.01 | D187: 3.26 | E187: 1.86 | F187: 342 | G187: Jacqueline Noble | H187: Regular Air | I187: Corporate | J187: Office Supplies | K187: Pens & Art Supplies | L187: Wrap Bag | M187: Avery Hi-Liter GlideStik Fluorescent Highlighter, Yellow Ink | N187: 0.41 | O187: United States | P187: South | Q187: Florida | R187: Miami | S187: 33181 | T187: 42128 | U187: 42130 | V187: -4.6683 | W187: 20 | X187: 73.97 | Y187: 3332
A188: 22784 | B188: Critical | C188: 0.03 | D188: 15.23 | E188: 27.75 | F188: 343 | G188: Lynn Epstein | H188: Delivery Truck | I188: Corporate | J188: Furniture | K188: Tables | L188: Jumbo Box | M188: Anderson Hickey Conga Table Tops & Accessories | N188: 0.76 | O188: United States | P188: East | Q188: Maine | R188: Bangor | S188: 4401 | T188: 42035 | U188: 42036 | V188: 11.65095 | W188: 7 | X188: 111.86 | Y188: 88151
A189: 18480 | B189: Critical | C189: 0.01 | D189: 3.26 | E189: 1.86 | F189: 344 | G189: Rosemary English | H189: Regular Air | I189: Corporate | J189: Office Supplies | K189: Pens & Art Supplies | L189: Wrap Bag | M189: Avery Hi-Liter GlideStik Fluorescent Highlighter, Yellow Ink | N189: 0.41 | O189: United States | P189: East | Q189: Maine | R189: Portland | S189: 4101 | T189: 42128 | U189: 42130 | V189: 0.702 | W189: 5 | X189: 18.49 | Y189: 88152
A190: 2408 | B190: Critical | C190: 0 | D190: 8.34 | E190: 2.64 | F190: 349 | G190: Kim Weiss | H190: Express Air | I190: Home Office | J190: Office Supplies | K190: Scissors, Rulers and Trimmers | L190: Small Pack | M190: Acme® Elite Stainless Steel Scissors | N190: 0.59 | O190: United States | P190: South | Q190: Florida | R190: Miami | S190: 33132 | T190: 42164 | U190: 42166 | V190: 5.8625 | W190: 23 | X190: 212.89 | Y190: 17446
A191: 1595 | B191: Medium | C191: 0.04 | D191: 99.23 | E191: 8.99 | F191: 349 | G191: Kim Weiss | H191: Regular Air | I191: Home Office | J191: Furniture | K191: Office Furnishings | L191: Small Pack | M191: GE 48" Fluorescent Tube, Cool White Energy Saver, 34 Watts, 30/Box | N191: 0.35 | O191: United States | P191: South | Q191: Florida | R191: Miami | S191: 33132 | T191: 42006 | U191: 42008 | V191: 1916.6757 | W191: 54 | X191: 5555.6 | Y191: 11527
A192: 20408 | B192: Critical | C192: 0 | D192: 8.34 | E192: 2.64 | F192: 351 | G192: Juanita Coley Knox | H192: Express Air | I192: Home Office | J192: Office Supplies | K192: Scissors, Rulers and Trimmers | L192: Small Pack | M192: Acme® Elite Stainless Steel Scissors | N192: 0.59 | O192: United States | P192: East | Q192: New York | R192: Watertown | S192: 13601 | T192: 42164 | U192: 42166 | V192: 10.5 | W192: 6 | X192: 55.54 | Y192: 88685
A193: 19595 | B193: Medium | C193: 0.04 | D193: 99.23 | E193: 8.99 | F193: 351 | G193: Juanita Coley Knox | H193: Regular Air | I193: Home Office | J193: Furniture | K193: Office Furnishings | L193: Small Pack | M193: GE 48" Fluorescent Tube, Cool White Energy Saver, 34 Watts, 30/Box | N193: 0.35 | O193: United States | P193: East | Q193: New York | R193: Watertown | S193: 13601 | T193: 42006 | U193: 42008 | V193: 993.8346 | W193: 14 | X193: 1440.34 | Y193: 88686
A194: 19107 | B194: Low | C194: 0.08 | D194: 4.89 | E194: 4.93 | F194: 353 | G194: Bonnie Chambers | H194: Express Air | I194: Home Office | J194: Technology | K194: Computer Peripherals | L194: Small Pack | M194: Maxell 3.5" DS/HD IBM-Formatted Diskettes, 10/Pack | N194: 0.66 | O194: United States | P194: West | Q194: Arizona | R194: Glendale | S194: 85301 | T194: 42138 | U194: 42138 | V194: -165.45 | W194: 17 | X194: 84.76 | Y194: 89647
A195: 19108 | B195: Low | C195: 0.07 | D195: 6.68 | E195: 6.92 | F195: 353 | G195: Bonnie Chambers | H195: Regular Air | I195: Home Office | J195: Office Supplies | K195: Paper | L195: Small Box | M195: Xerox 1898 | N195: 0.37 | O195: United States | P195: West | Q195: Arizona | R195: Glendale | S195: 85301 | T195: 42138 | U195: 42145 | V195: -141.12 | W195: 16 | X195: 104.84 | Y195: 89647
... A272: 21958 | B272: High | C272: 0.01 | D272: 20.98 | E272: 53.03 | F272: 508 | G272: Cameron Owens | H272: Delivery Truck | I272: Corporate | J272: Office Supplies | K272: Storage & Organization | L272: Jumbo Drum | M272: Tennsco Lockers, Gray | N272: 0.78 | O272: United States | P272: South | Q272: Kentucky | R272: Covington | S272: 41011 | T272: 42058 | U272: 42058 | V272: -282.0818 | W272: 5 | X272: 123 | Y272: 87356
A273: 18305 | B273: Critical | C273: 0.01 | D273: 128.24 | E273: 12.65 | F273: 508 | G273: Cameron Owens | H273: Regular Air | I273: Corporate | J273: Furniture | K273: Chairs & Chairmats | L273: Medium Box | M273: SAFCO Folding Chair Trolley | O273: United States | P273: South | Q273: Kentucky | R273: Covington | S273: 41011 | T273: 42112 | U273: 42115 | V273: 140.1354 | W273: 4 | X273: 554.08 | Y273: 87357
A274: 19895 | B274: Low | C274: 0.02 | D274: 48.04 | E274: 5.09 | F274: 510 | G274: Gregory Rao | H274: Regular Air | I274: Corporate | J274: Office Supplies | K274: Paper | L274: Small Box | M274: Xerox 1910 | N274: 0.37 | O274: United States | P274: West | Q274: California | R274: Manteca | S274: 95336 | T274: 42017 | U274: 42017 | V274: 105.2526 | W274: 3 | X274: 152.54 | Y274: 90058
A275: 20007 | B275: Critical | C275: 0.03 | D275: 6.37 | E275: 5.19 | F275: 510 | G275: Gregory Rao | H275: Regular Air | I275: Corporate | J275: Office Supplies | K275: Binders and Binder Accessories | L275: Small Box | M275: C-Line Peel & Stick Add-On Filing Pockets, 8-3/4 x 5-1/8, 10/Pack | N275: 0.38 | O275: United States | P275: West | Q275: California | R275: Manteca | S275: 95336 | T275: 42036 | U275: 42037 | V275: -29.0927 | W275: 14 | X275: 89.79 | Y275: 90059
A276: 20216 | B276: Low | C276: 0.07 | D276: 12.64 | E276: 4.98 | F276: 518 | G276: Mark Ritchie | H276: Regular Air | I276: Home Office | J276: Furniture | K276: Office Furnishings | L276: Small Pack | M276: Nu-Dell Executive Frame | N276: 0.48 | O276: United States | P276: Central | Q276: Missouri | R276: Clayton | S276: 63105 | T276: 42160 | U276: 42167 | V276: 113.415 | W276: 16 | X276: 199.76 | Y276: 90867
A277: 23200 | B277: Medium | C277: 0.02 | D277: 150.98 | E277: 13.99 | F277: 522 | G277: Aaron Riggs | H277: Express Air | I277: Small Business | J277: Technology | K277: Office Machines | L277: Medium Box | M277: Canon MP41DH Printing Calculator | N277: 0.38 | O277: United States | P277: West | Q277: Oregon | R277: Redmond | S277: 97756 | T277: 42177 | U277: 42179 | V277: 26.1 | W277: 3 | X277: 480.37 | Y277: 89327
A278: 23201 | B278: Medium | C278: 0.1 | D278: 5.43 | E278: 0.95 | F278: 522 | G278: Aaron Riggs | H278: Regular Air | I278: Small Business | J278: Office Supplies | K278: Paper | L278: Wrap Bag | M278: Wirebound Message Book, 4 per Page | N278: 0.36 | O278: United States | P278: West | Q278: Oregon | R278: Redmond | S278: 97756 | T278: 42177 | U278: 42179 | V278: -2.58 | W278: 1 | X278: 5.76 | Y278: 89327
A279: 23202 | B279: Medium | C279: 0.01 | D279: 179.29 | E279: 29.21 | F279: 522 | G279: Aaron Riggs | H279: Delivery Truck | I279: Small Business | J279: Furniture | K279: Tables | L279: Jumbo Box | M279: Bevis Round Conference Table Top, X-Base | N279: 0.74 | O279: United States | P279: West | Q279: Oregon | R279: Redmond | S279: 97756 | T279: 42177 | U279: 42178 | V279: 2800.12 | W279: 21 | X279: 3112.13 | Y279: 89327
A280: 21517 | B280: Not Specified | C280: 0.03 | D280: 1270.99 | E280: 19.99 | F280: 524 | G280: Gina McKnight | H280: Regular Air | I280: Consumer | J280: Office Supplies | K280: Binders and Binder Accessories | L280: Small Box | M280: Fellowes PB500 Electric Punch Plastic Comb Binding Machine with Manual Bind | N280: 0.35 | O280: United States | P280: South | Q280: Tennessee | R280: Farragut | S280: 37922 | T280: 42024 | U280: 42026 | V280: 363.552 | W280: 2 | X280: 2589.01 | Y280: 91127
A281: 21518 | B281: Not Specified | C281: 0.07 | D281: 2036.48 | E281: 14.7 | F281: 524 | G281: Gina McKnight | H281: Delivery Truck | I281: Consumer | J281: Technology | K281: Office Machines | L281: Jumbo Drum | M281: Lexmark 4227 Plus Dot Matrix Printer | N281: 0.55 | O281: United States | P281: South | Q281: Tennessee | R281: Farragut | S281: 37922 | T281: 42024 | U281: 42026 | V281: -11.536 | W281: 1 | X281: 1893.93 | Y281: 91127
A282: 22176 | B282: High | C282: 0.09 | D282: 17.98 | E282: 8.51 | F282: 526 | G282: April Hu | H282: Regular Air | I282: Home Office | J282: Technology | K282: Office Machines | L282: Medium Box | M282: Canon P1-DHIII Palm Printing Calculator | N282: 0.4 | O282: United States | P282: West | Q282: Arizona | R282: Mesa | S282: 85204 | T282: 42149 | U282: 42151 | V282: -6.612 | W282: 12 | X282: 211.13 | Y282: 90026
A283: 20494 | B283: Not Specified | C283: 0 | D283: 1.88 | E283: 1.49 | F283: 526 | G283: April Hu | H283: Regular Air | I283: Home Office | J283: Office Supplies | K283: Binders and Binder Accessories | L283: Small Box | M283: Staples® General Use 3-Ring Binders | N283: 0.37 | O283: United States | P283: West | Q283: Arizona | R283: Mesa | S283: 85204 | T283: 42021 | U283: 42022 | V283: -15.5595 | W283: 13 | X283: 25.39 | Y283: 90027
A284: 20495 | B284: Not Specified | C284: 0.06 | D284: 5.78 | E284: 5.67 | F284: 526 | G284: April Hu | H284: Regular Air | I284: Home Office | J284: Office Supplies | K284: Paper | L284: Small Box | M284: Xerox 1978 | N284: 0.36 | O284: United States | P284: West | Q284: Arizona | R284: Mesa | S284: 85204 | T284: 42021 | U284: 42022 | V284: -108.19 | W284: 15 | X284: 87.27 | Y284: 90027
...

Sheet Users
A1: Region | B1: Manager
A2: Central | B2: Chris
A3: East | B3: Erin
A4: South | B4: Sam
A5: West | B5: William

Sheet выручка по менеджерам
E5: Процент выручки по менеджерам
E6: менеджер | F6: выручка
E7: Chris | F7: 448284.7
E8: Erin | F8: 592171.49
E9: Sam | F9: 357105.12
E10: William | F10: 526776.57
E11: Общий итог | F11: 1924337.9

Sheet kpi
C4: выручка | D4: прибыль | E4: средний чек
C5: 1924337.9 | D5: 224077.61 | E5: 1409.7713

Sheet выручка от даты
B3: выручка, тыс.
B4: Названия строк | C4: выручка | D4: выручка2
B5: янв | C5: 274766.92 | D5: 274766.92
B6: фев | C6: 326101.47 | D6: 326101.47
B7: мар | C7: 271696.67 | D7: 271696.67
B8: апр | C8: 389831.95 | D8: 389831.95
B9: май | C9: 306572.07 | D9: 306572.07
B10: июн | C10: 355368.8 | D10: 355368.8

Sheet покупатели
B4: Названия строк | C4: выручка
B5: Aaron Day | C5: 710.16
B6: Aaron Dillon | C6: 18.34
B7: Aaron Riggs | C7: 3598.26
B8: Aaron Shaffer | C8: 894.64
B9: Adam G Sawyer | C9: 1638.5
B10: Adam Saunders Gray | C10: 48.3
B11: Albert Frost | C11: 485.01
B12: Albert Maxwell | C12: 396.19
B13: Albert Tyson | C13: 1338.6
B14: Alex Harrell | C14: 267.89
B15: Alex Nicholson | C15: 191.68
B16: Alex Watkins | C16: 205.76
... B1135: Общий итог | C1135: 1924337.9

Sheet топ 5 товаров
B2: топ 5 товаров
B3: Названия строк | C3: выручка
B4: Polycom ViewStation™ ISDN Videoconferencing Unit | C4: 46538.69
B5: Okidata ML395C Color Dot Matrix Printer | C5: 47611.09
B6: Global Troy™ Executive Leather Low-Back Tilter | C6: 50871.21
B7: Lexmark 4227 Plus Dot Matrix Printer | C7: 61071.73
B8: Fellowes PB500 Electric Punch Plastic Comb Binding Machine with Manual Bind | C8: 69013.48

Sheet сегмент
B2: доход по сегменту покупателя
B3: Названия строк | C3: выручка
B4: Corporate | C4: 657784.53
B5: Home Office | C5: 464481.04
B6: Consumer | C6: 401778.37
B7: Small Business | C7: 400293.94
B8: Общий итог | C8: 1924337.9

Sheet Дашборд

Sheet формулы
B7: Order ID | C7: Order Date | D7: Product_id | E7: Profit | F7: Region | G7: Product_name | H7: Manager | I7: Is_Xerox | O7: Прибыль для каждого менеджера в феврале
B8: 86838 | C8: 42136 | D8: 4 | E8: 803.4705 | F8: Central | G8: =VLOOKUP(D8,products[],4,0) -> Howard Miller 12-3/4 Diameter Accuwave DS ™ Wall Clock | H8: =INDEX(Таблица3[],MATCH(формулы!F8,Таблица3[Region],0),2) -> Chris | I8: =IF(ISNUMBER(SEARCH("Xerox",G8)), "да", "нет") -> нет
B9: 91304 | C9: 42050 | D9: 4 | E9: 465.4395 | F9: West | G9: =VLOOKUP(D9,products[],4,0) -> Howard Miller 12-3/4 Diameter Accuwave DS ™ Wall Clock | H9: =INDEX(Таблица3[],MATCH(формулы!F9,Таблица3[Region],0),2) -> William | I9: =IF(ISNUMBER(SEARCH("Xerox",G9)), "да", "нет") -> нет | K9: =COUNTIF(I8:I1959, "да") -> 173 | O9: Chris | P9: Erin | Q9: Sam | R9: William
B10: 91454 | C10: 42134 | D10: 24 | E10: 25.91382 | F10: West | G10: =VLOOKUP(D10,products[],4,0) -> AT&T 2230 Dual Handset Phone With Caller ID/Call Waiting | H10: =INDEX(Таблица3[],MATCH(формулы!F10,Таблица3[Region],0),2) -> William | I10: =IF(ISNUMBER(SEARCH("Xerox",G10)), "да", "нет") -> нет | O10: =SUMIFS($E$8:$E$1959,$C$8:$C$1959,"<01.03.2015",$C$8:$C$1959,">=01.02.2015",$H$8:$H$1959,O9) -> 19971.093 | P10: =SUMIFS($E$8:$E$1959,$C$8:$C$1959,"<01.03.2015",$C$8:$C$1959,">=01.02.2015",$H$8:$H$1959,P9) -> -3273.2288 | Q10: =SUMIFS($E$8:$E$1959,$C$8:$C$1959,"<01.03.2015",$C$8:$C$1959,">=01.02.2015",$H$8:$H$1959,Q9) -> -8583.7102 | R10: =SUMIFS($E$8:$E$1959,$C$8:$C$1959,"<01.03.2015",$C$8:$C$1959,">=01.02.2015",$H$8:$H$1959,R9) -> 27830.505
B11: 87366 | C11: 42093 | D11: 40 | E11: 7402.32 | F11: East | G11: =VLOOKUP(D11,products[],4,0) -> GBC DocuBind TL300 Electric Binding System | H11: =INDEX(Таблица3[],MATCH(формулы!F11,Таблица3[Region],0),2) -> Erin | I11: =IF(ISNUMBER(SEARCH("Xerox",G11)), "да", "нет") -> нет
B12: 85826 | C12: 42012 | D12: 40 | E12: 3602.1312 | F12: West | G12: =VLOOKUP(D12,products[],4,0) -> GBC DocuBind TL300 Electric Binding System | H12: =INDEX(Таблица3[],MATCH(формулы!F12,Таблица3[Region],0),2) -> William | I12: =IF(ISNUMBER(SEARCH("Xerox",G12)), "да", "нет") -> нет
B13: 90596 | C13: 42158 | D13: 41 | E13: 1892.424 | F13: West | G13: =VLOOKUP(D13,products[],4,0) -> Fellowes Super Stor/Drawer® Files | H13: =INDEX(Таблица3[],MATCH(формулы!F13,Таблица3[Region],0),2) -> William | I13: =IF(ISNUMBER(SEARCH("Xerox",G13)), "да", "нет") -> нет
B14: 88921 | C14: 42096 | D14: 41 | E14: 1167.158 | F14: Central | G14: =VLOOKUP(D14,products[],4,0) -> Fellowes Super Stor/Drawer® Files | H14: =INDEX(Таблица3[],MATCH(формулы!F14,Таблица3[Region],0),2) -> Chris | I14: =IF(ISNUMBER(SEARCH("Xerox",G14)), "да", "нет") -> нет
B15: 51072 | C15: 42096 | D15: 41 | E15: 1014.92 | F15: Central | G15: =VLOOKUP(D15,products[],4,0) -> Fellowes Super Stor/Drawer® Files | H15: =INDEX(Таблица3[],MATCH(формулы!F15,Таблица3[Region],0),2) -> Chris | I15: =IF(ISNUMBER(SEARCH("Xerox",G15)), "да", "нет") -> нет
B16: 88174 | C16: 42006 | D16: 41 | E16: -7.58 | F16: Central | G16: =VLOOKUP(D16,products[],4,0) -> Fellowes Super Stor/Drawer® Files | H16: =INDEX(Таблица3[],MATCH(формулы!F16,Таблица3[Region],0),2) -> Chris | I16: =IF(ISNUMBER(SEARCH("Xerox",G16)), "да", "нет") -> нет
B17: 86357 | C17: 42008 | D17: 41 | E17: 35.31 | F17: Central | G17: =VLOOKUP(D17,products[],4,0) -> Fellowes Super Stor/Drawer® Files | H17: =INDEX(Таблица3[],MATCH(формулы!F17,Таблица3[Region],0),2) -> Chris | I17: =IF(ISNUMBER(SEARCH("Xerox",G17)), "да", "нет") -> нет
B18: 91424 | C18: 42071 | D18: 41 | E18: 664.518 | F18: South | G18: =VLOOKUP(D18,products[],4,0) -> Fellowes Super Stor/Drawer® Files | H18: =INDEX(Таблица3[],MATCH(формулы!F18,Таблица3[Region],0),2) -> Sam | I18: =IF(ISNUMBER(SEARCH("Xerox",G18)), "да", "нет") -> нет
B19: 38087 | C19: 42056 | D19: 85 | E19: -76.89 | F19: West | G19: =VLOOKUP(D19,products[],4,0) -> Zoom V.92 USB External Faxmodem | H19: =INDEX(Таблица3[],MATCH(формулы!F19,Таблица3[Region],0),2) -> William | I19: =IF(ISNUMBER(SEARCH("Xerox",G19)), "да", "нет") -> нет
B20: 88360 | C20: 42056 | D20: 85 | E20: -76.89 | F20: East | G20: =VLOOKUP(D20,products[],4,0) -> Zoom V.92 USB External Faxmodem | H20: =INDEX(Таблица3[],MATCH(формулы!F20,Таблица3[Region],0),2) -> Erin | I20: =IF(ISNUMBER(SEARCH("Xerox",G20)), "да", "нет") -> нет
B21: 11206 | C21: 42183 | D21: 85 | E21: -17.03 | F21: East | G21: =VLOOKUP(D21,products[],4,0) -> Zoom V.92 USB External Faxmodem | H21: =INDEX(Таблица3[],MATCH(формулы!F21,Таблица3[Region],0),2) -> Erin | I21: =IF(ISNUMBER(SEARCH("Xerox",G21)), "да", "нет") -> нет
B22: 87587 | C22: 42183 | D22: 85 | E22: -8.515 | F22: East | G22: =VLOOKUP(D22,products[],4,0) -> Zoom V.92 USB External Faxmodem | H22: =INDEX(Таблица3[],MATCH(формулы!F22,Таблица3[Region],0),2) -> Erin | I22: =IF(ISNUMBER(SEARCH("Xerox",G22)), "да", "нет") -> нет
... B1959: 90987 | C1959: 42118 | D1959: 901 | E1959: 23.046 | F1959: West | G1959: =VLOOKUP(D1959,products[],4,0) -> DIXON Ticonderoga® Erasable Checking Pencils | H1959: =INDEX(Таблица3[],MATCH(формулы!F1959,Таблица3[Region],0),2) -> William | I1959: =IF(ISNUMBER(SEARCH("Xerox",G1959)), "да", "нет") -> нет

Sheet Orders изм.
A1: Order ID | B1: Order Date | C1: City | D1: Country | E1: Customer ID | F1: Customer Segment | G1: Discount | H1: Order Priority | I1: Postal Code | J1: Product_id | K1: Product Base Margin | L1: Product Container | M1: Profit | N1: Quantity ordered new | O1: Region | P1: Sales | Q1: Ship Date | R1: Ship Mode | S1: Shipping Cost | T1: State or Province | U1: Unit Price | V1: месяц | W1: Custom | X1: месяц (Индекс месяца) | Y1: месяц (Месяц)
A2: 86838 | B2: 42136 | C2: Prior Lake | D2: United States | E2: 14 | F2: Small Business | G2: 0.09 | H2: Medium | I2: 55372 | J2: 4 | K2: 0.43 | L2: Small Box | M2: 803.4705 | N2: 16 | O2: Central | P2: 1164.45 | Q2: 14.05.2015 | R2: Regular Air | S2: 19.99 | T2: Minnesota | U2: 78.69 | V2: 42136 | W2: Май | X2: 5 | Y2: май
A3: 91304 | B3: 42050 | C3: Coachella | D3: United States | E3: 2355 | F3: Consumer | G3: 0.1 | H3: Not Specified | I3: 92236 | J3: 4 | K3: 0.43 | L3: Small Box | M3: 465.4395 | N3: 9 | O3: West | P3: 674.55 | Q3: 16.02.2015 | R3: Regular Air | S3: 19.99 | T3: California | U3: 78.69 | V3: 42050 | W3: Февраль | X3: 2 | Y3: фев
A4: 91454 | B4: 42134 | C4: Redmond | D4: United States | E4: 43 | F4: Consumer | G4: 0 | H4: High | I4: 98052 | J4: 24 | K4: 0.52 | L4: Small Box | M4: 25.91382 | N4: 6 | O4: West | P4: 647.07 | Q4: 11.05.2015 | R4: Regular Air | S4: 19.99 | T4: Washington | U4: 99.99 | V4: 42134 | W4: Май | X4: 5 | Y4: май
A5: 87366 | B5: 42093 | C5: Cincinnati | D5: United States | E5: 84 | F5: Corporate | G5: 0.08 | H5: High | I5: 45231 | J5: 40 | K5: 0.38 | L5: Small Box | M5: 7402.32 | N5: 13 | O5: East | P5: 10728 | Q5: 02.04.2015 | R5: Regular Air | S5: 19.99 | T5: Ohio | U5: 896.99 | V5: 42093 | W5: Март | X5: 3 | Y5: мар
A6: 85826 | B6: 42012 | C6: Edmonds | D6: United States | E6: 2868 | F6: Corporate | G6: 0.03 | H6: High | I6: 98026 | J6: 40 | K6: 0.38 | L6: Small Box | M6: 3602.1312 | N6: 6 | O6: West | P6: 5220.48 | Q6: 10.01.2015 | R6: Regular Air | S6: 19.99 | T6: Washington | U6: 896.99 | V6: 42012 | W6: Январь | X6: 1 | Y6: янв
A7: 90596 | B7: 42158 | C7: Vacaville | D7: United States | E7: 87 | F7: Corporate | G7: 0.05 | H7: Low | I7: 95687 | J7: 41 | K7: 0.66 | L7: Small Box | M7: 1892.424 | N7: 19 | O7: West | P7: 3127.69 | Q7: 08.06.2015 | R7: Regular Air | S7: 19.99 | T7: California | U7: 161.55 | V7: 42158 | W7: Июнь | X7: 6 | Y7: июн
A8: 88921 | B8: 42096 | C8: Overland Park | D8: United States | E8: 197 | F8: Small Business | G8: 0 | H8: Critical | I8: 66212 | J8: 41 | K8: 0.66 | L8: Small Box | M8: 1167.158 | N8: 19 | O8: Central | P8: 3108.98 | Q8: 04.04.2015 | R8: Regular Air | S8: 19.99 | T8: Kansas | U8: 161.55 | V8: 42096 | W8: Апрель | X8: 4 | Y8: апр
A9: 51072 | B9: 42096 | C9: Detroit | D9: United States | E9: 198 | F9: Small Business | G9: 0 | H9: Critical | I9: 48138 | J9: 41 | K9: 0.66 | L9: Small Box | M9: 1014.92 | N9: 77 | O9: Central | P9: 12599.55 | Q9: 04.04.2015 | R9: Regular Air | S9: 19.99 | T9: Michigan | U9: 161.55 | V9: 42096 | W9: Апрель | X9: 4 | Y9: апр
A10: 88174 | B10: 42006 | C10: Raytown | D10: United States | E10: 674 | F10: Small Business | G10: 0.06 | H10: Critical | I10: 64133 | J10: 41 | K10: 0.66 | L10: Small Box | M10: -7.58 | N10: 3 | O10: Central | P10: 485.01 | Q10: 03.01.2015 | R10: Regular Air | S10: 19.99 | T10: Missouri | U10: 161.55 | V10: 42006 | W10: Январь | X10: 1 | Y10: янв
A11: 86357 | B11: 42008 | C11: Burleson | D11: United States | E11: 916 | F11: Corporate | G11: 0.05 | H11: Low | I11: 76028 | J11: 41 | K11: 0.66 | L11: Small Box | M11: 35.31 | N11: 3 | O11: Central | P11: 499.31 | Q11: 11.01.2015 | R11: Regular Air | S11: 19.99 | T11: Texas | U11: 161.55 | V11: 42008 | W11: Январь | X11: 1 | Y11: янв
A12: 91424 | B12: 42071 | C12: Waynesboro | D12: United States | E12: 2750 | F12: Small Business | G12: 0.02 | H12: Critical | I12: 22980 | J12: 41 | K12: 0.66 | L12: Small Box | M12: 664.518 | N12: 4 | O12: South | P12: 657.61 | Q12: 08.03.2015 | R12: Regular Air | S12: 19.99 | T12: Virginia | U12: 161.55 | V12: 42071 | W12: Март | X12: 3 | Y12: мар
A13: 38087 | B13: 42056 | C13: San Francisco | D13: United States | E13: 181 | F13: Small Business | G13: 0.02 | H13: Critical | I13: 94122 | J13: 85 | K13: 0.41 | L13: Small Box | M13: -76.89 | N13: 18 | O13: West | P13: 901.81 | Q13: 21.02.2015 | R13: Regular Air | S13: 19.99 | T13: California | U13: 49.99 | V13: 42056 | W13: Февраль | X13: 2 | Y13: фев
... A1017: 90888 | B1017: 42130 | C1017: Midland | D1017: United States | E1017: 1986 | F1017: Home Office | G1017: 0.05 | H1017: Not Specified | I1017: 79701 | J1017: 146 | K1017: 0.6 | L1017: Medium Box | M1017: 5.687 | N1017: 4 | O1017: Central | P1017: 42.99 | Q1017: 08.05.2015 | R1017: Express Air | S1017: 5.03 | T1017: Texas | U1017: 7.99 | V1017: 42130 | W1017: Май | X1017: 5 | Y1017: май
A1018: 89789 | B1018: 42068 | C1018: Berkeley | D1018: United States | E1018: 3048 | F1018: Corporate | G1018: 0.06 | H1018: High | I1018: 94704 | J1018: 148 | L1018: Large Box | M1018: 1167.38 | N1018: 10 | O1018: West | P1018: 2610.56 | Q1018: 07.03.2015 | R1018: Express Air | S1018: 24.49 | T1018: California | U1018: 276.2 | V1018: 42068 | W1018: Март | X1018: 3 | Y1018: мар
A1019: 89647 | B1019: 42138 | C1019: Glendale | D1019: United States | E1019: 353 | F1019: Home Office | G1019: 0.08 | H1019: Low | I1019: 85301 | J1019: 155 | K1019: 0.66 | L1019: Small Pack | M1019: -165.45 | N1019: 17 | O1019: West | P1019: 84.76 | Q1019: 14.05.2015 | R1019: Express Air | S1019: 4.93 | T1019: Arizona | U1019: 4.89 | V1019: 42138 | W1019: Май | X1019: 5 | Y1019: май
A1020: 90292 | B1020: 42105 | C1020: Oakland | D1020: United States | E1020: 369 | F1020: Corporate | G1020: 0.09 | H1020: Low | I1020: 94601 | J1020: 160 | K1020: 0.44 | L1020: Small Pack | M1020: 211.232 | N1020: 21 | O1020: West | P1020: 394.1 | Q1020: 13.04.2015 | R1020: Express Air | S1020: 6.15 | T1020: California | U1020: 19.23 | V1020: 42105 | W1020: Апрель | X1020: 4 | Y1020: апр
A1021: 90751 | B1021: 42055 | C1021: Kissimmee | D1021: United States | E1021: 3284 | F1021: Corporate | G1021: 0.05 | H1021: High | I1021: 34741 | J1021: 160 | K1021: 0.44 | L1021: Small Pack | M1021: -2133.278 | N1021: 6 | O1021: South | P1021: 119.78 | Q1021: 22.02.2015 | R1021: Express Air | S1021: 6.15 | T1021: Florida | U1021: 19.23 | V1021: 42055 | W1021: Февраль | X1021: 2 | Y1021: фев
A1022: 85834 | B1022: 42094 | C1022: Indian Trail | D1022: United States | E1022: 2066 | F1022: Home Office | G1022: 0.09 | H1022: Critical | I1022: 28079 | J1022: 161 | K1022: 0.58 | L1022: Medium Box | M1022: 272.694 | N1022: 2 | O1022: South | P1022: 38.98 | Q1022: 01.04.2015 | R1022: Express Air | S1022: 4.81 | T1022: North Carolina | U1022: 20.99 | V1022: 42094 | W1022: Март | X1022: 3 | Y1022: мар
A1023: 87847 | B1023: 42140 | C1023: Yuba City | D1023: United States | E1023: 1042 | F1023: Small Business | G1023: 0 | H1023: Critical | I1023: 95991 | J1023: 195 | K1023: 0.52 | L1023: Medium Box | M1023: 9.33 | N1023: 6 | O1023: West | P1023: 98.96 | Q1023: 17.05.2015 | R1023: Express Air | S1023: 6.75 | T1023: California | U1023: 14.42 | V1023: 42140 | W1023: Май | X1023: 5 | Y1023: май
A1024: 87993 | B1024: 42011 | C1024: Franklin Square | D1024: United States | E1024: 1606 | F1024: Home Office | G1024: 0.07 | H1024: Medium | I1024: 11010 | J1024: 200 | K1024: 0.41 | L1024: Large Box | M1024: -2870.2776 | N1024: 1 | O1024: East | P1024: 706.56 | Q1024: 08.01.2015 | R1024: Express Air | S1024: 24.49 | T1024: New York | U1024: 699.99 | V1024: 42011 | W1024: Январь | X1024: 1 | Y1024: янв
A1025: 87033 | B1025: 42160 | C1025: Bangor | D1025: United States | E1025: 2507 | F1025: Home Office | G1025: 0.06 | H1025: Medium | I1025: 4401 | J1025: 200 | K1025: 0.41 | L1025: Large Box | M1025: 7024.2069 | N1025: 15 | O1025: East | P1025: 10180.01 | Q1025: 07.06.2015 | R1025: Express Air | S1025: 24.49 | T1025: Maine | U1025: 699.99 | V1025: 42160 | W1025: Июнь | X1025: 6 | Y1025: июн
A1026: 88587 | B1026: 42063 | C1026: Camarillo | D1026: United States | E1026: 3355 | F1026: Corporate | G1026: 0.08 | H1026: Low | I1026: 93010 | J1026: 208 | K1026: 0.74 | L1026: Small Pack | M1026: -41.83 | N1026: 6 | O1026: West | P1026: 48.99 | Q1026: 04.03.2015 | R1026: Express Air | S1026: 2.38 | T1026: California | U1026: 8.32 | V1026: 42063 | W1026: Февраль | X1026: 2 | Y1026: фев
A1027: 89327 | B1027: 42177 | C1027: Redmond | D1027: United States | E1027: 522 | F1027: Small Business | G1027: 0.02 | H1027: Medium | I1027: 97756 | J1027: 217 | K1027: 0.38 | L1027: Medium Box | M1027: 26.1 | N1027: 3 | O1027: West | P1027: 480.37 | Q1027: 24.06.2015 | R1027: Express Air | S1027: 13.99 | T1027: Oregon | U1027: 150.98 | V1027: 42177 | W1027: Июнь | X1027: 6 | Y1027: июн
A1028: 86899 | B1028: 42030 | C1028: Saint Petersburg | D1028: United States | E1028: 3154 | F1028: Corporate | G1028: 0.08 | H1028: High | I1028: 33710 | J1028: 217 | K1028: 0.38 | L1028: Medium Box | M1028: -3.948 | N1028: 8 | O1028: South | P1028: 1183.82 | Q1028: 27.01.2015 | R1028: Express Air | S1028: 13.99 | T1028: Florida | U1028: 150.98 | V1028: 42030 | W1028: Январь | X1028: 1 | Y1028: янв
A1029: 86250 | B1029: 42169 | C1029: Morgantown | D1029: United States | E1029: 547 | F1029: Corporate | G1029: 0.03 | H1029: Not Specified | I1029: 26501 | J1029: 227 | K1029: 0.54 | L1029: Wrap Bag | M1029: 39.5853 | N1029: 4 | O1029: East | P1029: 57.37 | Q1029: 15.06.2015 | R1029: Express Air | S1029: 6.85 | T1029: West Virginia | U1029: 13.73 | V1029: 42169 | W1029: Июнь | X1029: 6 | Y1029: июн
A1030: 17155 | B1030: 42032 | C1030: Los Angeles | D1030: United States | E1030: 553 | F1030: Home Office | G1030: 0 | H1030: Medium | I1030: 90008 | J1030: 233 | K1030: 0.39 | L1030: Wrap Bag | M1030: 34.068 | N1030: 36 | O1030: West | P1030: 267.53 | Q1030: 29.01.2015 | R1030: Express Air | S1030: 2 | T1030: California | U1030: 6.88 | V1030: 42032 | W1030: Январь | X1030: 1 | Y1030: янв
... A1082: 87570 | B1082: 42053 | C1082: Durango | D1082: United States | E1082: 2141 | F1082: Home Office | G1082: 0.03 | H1082: High | I1082: 81301 | J1082: 695 | K1082: 0.59 | L1082: Small Pack | M1082: 12.5504 | N1082: 7 | O1082: West | P1082: 154.11 | Q1082: 19.02.2015 | R1082: Express Air | S1082: 5.53 | T1082: Colorado | U1082: 22.01 | V1082: 42053 | W1082: Февраль | X1082: 2 | Y1082: фев
A1083: 88028 | B1083: 42005 | C1083: Bowie | D1083: United States | E1083: 2211 | F1083: Home Office | G1083: 0.08 | H1083: Not Specified | I1083: 20715 | J1083: 712 | L1083: Large Box | M1083: -425.2084 | N1083: 2 | O1083: East | P1083: 193.88 | Q1083: 03.01.2015 | R1083: Express Air | S1083: 35 | T1083: Maryland | U1083: 95.99 | V1083: 42005 | W1083: Январь | X1083: 1 | Y1083: янв
A1084: 90110 | B1084: 42079 | C1084: Harker Heights | D1084: United States | E1084: 2272 | F1084: Corporate | G1084: 0.08 | H1084: High | I1084: 76543 | J1084: 723 | K1084: 0.56 | L1084: Small Pack | M1084: -37.6 | N1084: 5 | O1084: Central | P1084: 78.08 | Q1084: 18.03.2015 | R1084: Express Air | S1084: 7.42 | T1084: Texas | U1084: 15.73 | V1084: 42079 | W1084: Март | X1084: 3 | Y1084: мар
A1085: 89218 | B1085: 42026 | C1085: Mobile | D1085: United States | E1085: 2456 | F1085: Home Office | G1085: 0.02 | H1085: High | I1085: 36608 | J1085: 757 | K1085: 0.67 | L1085: Medium Box | M1085: -905.9904 | N1085: 11 | O1085: South | P1085: 1009.93 | Q1085: 23.01.2015 | R1085: Express Air | S1085: 39.61 | T1085: Alabama | U1085: 92.23 | V1085: 42026 | W1085: Январь | X1085: 1 | Y1085: янв
A1086: 86886 | B1086: 42016 | C1086: Costa Mesa | D1086: United States | E1086: 2490 | F1086: Home Office | G1086: 0 | H1086: Not Specified | I1086: 92627 | J1086: 767 | K1086: 0.41 | L1086: Small Pack | M1086: 82.7034 | N1086: 11 | O1086: West | P1086: 119.86 | Q1086: 14.01.2015 | R1086: Express Air | S1086: 1.99 | T1086: California | U1086: 10.01 | V1086: 42016 | W1086: Январь | X1086: 1 | Y1086: янв
A1087: 23877 | B1087: 42016 | C1087: Los Angeles | D1087: United States | E1087: 2491 | F1087: Home Office | G1087: 0 | H1087: Not Specified | I1087: 90045 | J1087: 767 | K1087: 0.41 | L1087: Small Pack | M1087: 128.03 | N1087: 42 | O1087: West | P1087: 457.63 | Q1087: 14.01.2015 | R1087: Express Air | S1087: 1.99 | T1087: California | U1087: 10.01 | V1087: 42016 | W1087: Январь | X1087: 1 | Y1087: янв
A1088: 88016 | B1088: 42082 | C1088: Brentwood | D1088: United States | E1088: 2621 | F1088: Corporate | G1088: 0.03 | H1088: High | I1088: 37027 | J1088: 787 | K1088: 0.59 | L1088: Small Pack | M1088: -177.058 | N1088: 5 | O1088: South | P1088: 207.22 | Q1088: 20.03.2015 | R1088: Express Air | S1088: 8.99 | T1088: Tennessee | U1088: 40.97 | V1088: 42082 | W1088: Март | X1088: 3 | Y1088: мар
A1089: 90103 | B1089: 42121 | C1089: Jackson | D1089: United States | E1089: 3320 | F1089: Small Business | G1089: 0.09 | H1089: Not Specified | I1089: 38301 | J1089: 787 | K1089: 0.59 | L1089: Small Pack | M1089: 66.216 | N1089: 22 | O1089: South | P1089: 824.7 | Q1089: 29.04.2015 | R1089: Express Air | S1089: 8.99 | T1089: Tennessee | U1089: 40.97 | V1089: 42121 | W1089: Апрель | X1089: 4 | Y1089: апр
A1090: 86633 | B1090: 42171 | C1090: Winchester | D1090: United States | E1090: 2677 | F1090: Small Business | G1090: 0.03 | H1090: Critical | I1090: 22601 | J1090: 799 | K1090: 0.76 | L1090: Medium Box | M1090: -32.816 | N1090: 10 | O1090: South | P1090: 419.27 | Q1090: 17.06.2015 | R1090: Express Air | S1090: 58.66 | T1090: Virginia | U1090: 41.32 | V1090: 42171 | W1090: Июнь | X1090: 6 | Y1090: июн
A1091: 88611 | B1091: 42131 | C1091: Louisville | D1091: United States | E1091: 2962 | F1091: Consumer | G1091: 0.07 | H1091: High | I1091: 80027 | J1091: 818 | K1091: 0.39 | L1091: Wrap Bag | M1091: 33.3477 | N1091: 10 | O1091: West | P1091: 48.33 | Q1091: 09.05.2015 | R1091: Express Air | S1091: 0.88 | T1091: Colorado | U1091: 4.76 | V1091: 42131 | W1091: Май | X1091: 5 | Y1091: май
A1092: 89743 | B1092: 42156 | C1092: Newark | D1092: United States | E1092: 2817 | F1092: Corporate | G1092: 0.04 | H1092: High | I1092: 43055 | J1092: 825 | K1092: 0.35 | L1092: Small Pack | M1092: -18.3216 | N1092: 3 | O1092: East | P1092: 147.56 | Q1092: 02.06.2015 | R1092: Express Air | S1092: 1.25 | T1092: Ohio | U1092: 55.99 | V1092: 42156 | W1092: Июнь | X1092: 6 | Y1092: июн
A1093: 90296 | B1093: 42180 | C1093: Adrian | D1093: United States | E1093: 3261 | F1093: Consumer | G1093: 0.07 | H1093: Not Specified | I1093: 49221 | J1093: 829 | K1093: 0.61 | L1093: Large Box | M1093: 710.6724 | N1093: 10 | O1093: Central | P1093: 1029.96 | Q1093: 26.06.2015 | R1093: Express Air | S1093: 24.49 | T1093: Michigan | U1093: 105.34 | V1093: 42180 | W1093: Июнь | X1093: 6 | Y1093: июн
A1094: 88839 | B1094: 42119 | C1094: Kennesaw | D1094: United States | E1094: 3379 | F1094: Home Office | G1094: 0.05 | H1094: Critical | I1094: 30144 | J1094: 840 | K1094: 0.84 | L1094: Wrap Bag | M1094: 1628.37 | N1094: 18 | O1094: South | P1094: 59.22 | Q1094: 26.04.2015 | R1094: Express Air | S1094: 1.92 | T1094: Georgia | U1094: 3.14 | V1094: 42119 | W1094: Апрель | X1094: 4 | Y1094: апр
...

Sheet abc анализ
C2: Названия строк | D2: Выручка | E2: Выручка % от общего | F2: Выручка нарастающий % | G2: Группа ABC
C3: Office Machines | D3: 318169.68 | E3: 0.16533982 | F3: 0.16533982 | G3: =IF(F3 <= 80%, "A", IF(F3 <= 95%, "B", "C")) -> A | I3: группа | J3: A | K3: B | L3: C
C4: Chairs & Chairmats | D4: 261072.73 | E4: 0.13566886 | F4: 0.30100868 | G4: =IF(F4 <= 80%, "A", IF(F4 <= 95%, "B", "C")) -> A | I4: процент группы | J4: =COUNTIF($G$3:$G$19, J3) / COUNT($F$3:$G$19) -> 0.41176471 | K4: =COUNTIF($G$3:$G$19, K3) / COUNT($F$3:$G$19) -> 0.23529412 | L4: =COUNTIF($G$3:$G$19, L3) / COUNT($F$3:$G$19) -> 0.35294118
C5: Telephones and Communication | D5: 198764.49 | E5: 0.10328981 | F5: 0.40429849 | G5: =IF(F5 <= 80%, "A", IF(F5 <= 95%, "B", "C")) -> A | I5: процент выручки | J5: =SUMIF($G$3:$G$19, J3, $D$3:$D$19) / SUM($D$3:$D$19) -> 0.74982326 | K5: =SUMIF($G$3:$G$19, K3, $D$3:$D$19) / SUM($D$3:$D$19) -> 0.19518549 | L5: =SUMIF($G$3:$G$19, L3, $D$3:$D$19) / SUM($D$3:$D$19) -> 0.054991242
C6: Tables | D6: 193764.58 | E6: 0.10069156 | F6: 0.50499005 | G6: =IF(F6 <= 80%, "A", IF(F6 <= 95%, "B", "C")) -> A
C7: Binders and Binder Accessories | D7: 185928.14 | E7: 0.09661928 | F7: 0.60160933 | G7: =IF(F7 <= 80%, "A", IF(F7 <= 95%, "B", "C")) -> A
C8: Storage & Organization | D8: 177417.6 | E8: 0.092196699 | F8: 0.69380603 | G8: =IF(F8 <= 80%, "A", IF(F8 <= 95%, "B", "C")) -> A
C9: Bookcases | D9: 107796.09 | E9: 0.056017236 | F9: 0.74982326 | G9: =IF(F9 <= 80%, "A", IF(F9 <= 95%, "B", "C")) -> A
C10: Copiers and Fax | D10: 99069.48 | E10: 0.051482373 | F10: 0.80130564 | G10: =IF(F10 <= 80%, "A", IF(F10 <= 95%, "B", "C")) -> B
C11: Office Furnishings | D11: 98070.91 | E11: 0.050963457 | F11: 0.85226909 | G11: =IF(F11 <= 80%, "A", IF(F11 <= 95%, "B", "C")) -> B
C12: Computer Peripherals | D12: 96261.3 | E12: 0.050023076 | F12: 0.90229217 | G12: =IF(F12 <= 80%, "A", IF(F12 <= 95%, "B", "C")) -> B
C13: Appliances | D13: 82201.15 | E13: 0.042716589 | F13: 0.94500876 | G13: =IF(F13 <= 80%, "A", IF(F13 <= 95%, "B", "C")) -> B
C14: Paper | D14: 55813.92 | E14: 0.02900422 | F14: 0.97401298 | G14: =IF(F14 <= 80%, "A", IF(F14 <= 95%, "B", "C")) -> C
C15: Pens & Art Supplies | D15: 26071.61 | E15: 0.013548354 | F15: 0.98756133 | G15: =IF(F15 <= 80%, "A", IF(F15 <= 95%, "B", "C")) -> C
C16: Envelopes | D16: 10479.77 | E16: 0.0054459095 | F16: 0.99300724 | G16: =IF(F16 <= 80%, "A", IF(F16 <= 95%, "B", "C")) -> C
C17: Scissors, Rulers and Trimmers | D17: 6752.18 | E17: 0.0035088329 | F17: 0.99651607 | G17: =IF(F17 <= 80%, "A", IF(F17 <= 95%, "B", "C")) -> C
... C19: Rubber Bands | D19: 1789.43 | E19: 0.00092989387 | F19: 1 | G19: =IF(F19 <= 80%, "A", IF(F19 <= 95%, "B", "C")) -> C
C20: Общий итог | D20: 1924337.9 | E20: 1

Sheet products
A1: Product_id | B1: Product Category | C1: Product Sub-Category | D1: Product Name
A2: 15 | B2: Office Supplies | C2: Paper | D2: Xerox 194
A3: 27 | B3: Office Supplies | C3: Paper | D3: Xerox 1903
A4: 30 | B4: Office Supplies | C4: Paper | D4: Xerox 193
A5: 31 | B5: Office Supplies | C5: Paper | D5: Snap-A-Way® Black Print Carbonless Speed Message, No Reply Area, Duplicate
A6: 44 | B6: Office Supplies | C6: Paper | D6: Array® Memo Cubes
A7: 46 | B7: Office Supplies | C7: Paper | D7: REDIFORM Incoming/Outgoing Call Register, 11" X 8 1/2", 100 Messages
A8: 47 | B8: Office Supplies | C8: Paper | D8: Xerox 1897
A9: 56 | B9: Office Supplies | C9: Paper | D9: EcoTones® Memo Sheets
A10: 63 | B10: Office Supplies | C10: Paper | D10: Xerox 1939
A11: 65 | B11: Office Supplies | C11: Paper | D11: Xerox 1964
A12: 66 | B12: Office Supplies | C12: Paper | D12: Wirebound Message Books, 2 7/8" x 5", 3 Forms per Page
A13: 79 | B13: Office Supplies | C13: Paper | D13: Xerox 1952
... A914: 913 | B914: Furniture | C914: Office Furnishings | D914: Tenex 46" x 60" Computer Anti-Static Chairmat, Rectangular Shaped
